Workbook
Name FilterCategory: Dashboard!$H$7
Name FilterCity: Dashboard!$F$7
Name FilterMonthFrom: Dashboard!$B$7
Name FilterMonthTo: Dashboard!$D$7
Name FilterRep: Dashboard!$J$7

Sheet Dashboard
A1: SALES PERFORMANCE DASHBOARD
A3: FY 2025 | 1,287 Orders | Use the dropdown filters below to explore the data
A5: FILTERS
B6: Month From | D6: Month To | F6: City | H6: Category | J6: Sales Rep
B7: 2025-01 | D7: 2025-12 | F7: All | H7: All | J7: All
A9: KEY METRICS
A10: TOTAL SALES | D10: TOTAL PROFIT | G10: TOTAL ORDERS | J10: AVG ORDER VALUE
A11: =SUMPRODUCT(Dashboard_Data!$I$2:$I$1288,Dashboard_Data!$G$2:$G$1288) -> 93303190 | D11: =SUMPRODUCT(Dashboard_Data!$I$2:$I$1288,Dashboard_Data!$H$2:$H$1288) -> 18660578 | G11: =SUM(Dashboard_Data!$I$2:$I$1288) -> 1287 | J11: =IFERROR(SUMPRODUCT(Dashboard_Data!$I$2:$I$1288,Dashboard_Data!$G$2:$G$1288)/SUM(Dashboard_Data!$I$2:$I$1288),0) -> 72496.651
A13: VISUAL ANALYSIS
A49: Tip: Change the Month From / Month To / City / Category / Sales Rep dropdowns above to filter every KPI and chart on this dashboard.

Sheet Sheet1
A1: Order_ID | B1: Order_Date | C1: Customer_Name | D1: City | E1: Region | F1: Product_Category | G1: Product_Name | H1: Sales_Rep | I1: Units_Sold | J1: Unit_Price | K1: Total_Sales | L1: Payment_Method | M1: Discount_% | N1: Profit
A2: 1001 | B2: 2025-01-01 | C2: Neha Patil | D2: Hyderabad | E2: South | F2: Electronics | G2: Headphones | H2: Sneha | I2: 4 | J2: 20401 | K2: 73443.6 | L2: Credit Card | M2: 10 | N2: 21019.15
A3: 1002 | B3: 2025-01-01 | C3: Amit Shah | D3: Delhi | E3: North | F3: Electronics | G3: Headphones | H3: Ajay | I3: 4 | J3: 17480 | K3: 66424 | L3: Cash | M3: 5 | N3: 15368.62
A4: 1003 | B4: 2025-01-01 | C4: Karan Verma | D4: Hyderabad | E4: South | F4: Furniture | G4: Sofa | H4: Rahul | I4: 1 | J4: 20603 | K4: 18542.7 | L4: Debit Card | M4: 10 | N4: 3595.24
A5: 1004 | B5: 2025-01-02 | C5: Priya Sharma | D5: Hyderabad | E5: South | F5: Clothing | G5: T-Shirt | H5: Rahul | I5: 2 | J5: 35787 | K5: 71574 | L5: Debit Card | M5: 0 | N5: 10999.85
A6: 1005 | B6: 2025-01-02 | C6: Amit Shah | D6: Mumbai | E6: West | F6: Furniture | G6: Sofa | H6: Pooja | I6: 5 | J6: 41396 | K6: 206980 | L6: Cash | M6: 0 | N6: 34168.81
A7: 1006 | B7: 2025-01-03 | C7: Priya Sharma | D7: Hyderabad | E7: South | F7: Furniture | G7: Chair | H7: Ajay | I7: 5 | J7: 31592 | K7: 157960 | L7: Debit Card | M7: 0 | N7: 21390.53
A8: 1007 | B8: 2025-01-03 | C8: Neha Patil | D8: Pune | E8: West | F8: Electronics | G8: Headphones | H8: Rahul | I8: 3 | J8: 37915 | K8: 113745 | L8: Cash | M8: 0 | N8: 30022.96
A9: 1008 | B9: 2025-01-04 | C9: Rohit Mehta | D9: Mumbai | E9: West | F9: Electronics | G9: Headphones | H9: Rahul | I9: 1 | J9: 38859 | K9: 36916.05 | L9: UPI | M9: 5 | N9: 6036.85
A10: 1009 | B10: 2025-01-04 | C10: Karan Verma | D10: Mumbai | E10: West | F10: Clothing | G10: Jeans | H10: Sneha | I10: 3 | J10: 26304 | K10: 71020.8 | L10: UPI | M10: 10 | N10: 8473.11
A11: 1010 | B11: 2025-01-04 | C11: Amit Shah | D11: Mumbai | E11: West | F11: Clothing | G11: Jacket | H11: Rahul | I11: 5 | J11: 15994 | K11: 67974.5 | L11: Debit Card | M11: 15 | N11: 12850.43
A12: 1011 | B12: 2025-01-05 | C12: Neha Patil | D12: Mumbai | E12: West | F12: Electronics | G12: Headphones | H12: Ajay | I12: 3 | J12: 20557 | K12: 58587.45 | L12: Debit Card | M12: 5 | N12: 6595.92
A13: 1012 | B13: 2025-01-05 | C13: Priya Sharma | D13: Hyderabad | E13: South | F13: Electronics | G13: Laptop | H13: Ajay | I13: 1 | J13: 1926 | K13: 1829.7 | L13: Credit Card | M13: 5 | N13: 199.21
... A1288: 2287 | B1288: 2025-12-31 | C1288: Priya Sharma | D1288: Bangalore | E1288: South | F1288: Electronics | G1288: Laptop | H1288: Pooja | I1288: 3 | J1288: 24090 | K1288: 68656.5 | L1288: Debit Card | M1288: 5 | N1288: 19918.22

Sheet Sales_Report
A1: Sales Performance Report — FY 2025
A2: Source: Sheet1 | Period: 01 Jan 2025 – 31 Dec 2025 | 1,287 orders
A4: Key Performance Indicators (KPIs)
A5: Total Sales | C5: Total Profit | E5: Profit Margin | G5: Total Orders
A6: ₹93,303,190 | C6: ₹18,660,578 | E6: 20.0% | G6: 1,287
A8: Avg Order Value | C8: Units Sold | E8: Avg Discount | G8: Top Region
A9: ₹72,497 | C9: 3,889 | E9: 7.3% | G9: South
A12: Monthly Sales & Profit Trend
A13: Month | B13: Sales (₹) | C13: Profit (₹) | D13: Orders
A14: 2025-01 | B14: 8230898.8 | C14: 1554667.9 | D14: 108
A15: 2025-02 | B15: 6285791.3 | C15: 1291060.2 | D15: 102
A16: 2025-03 | B16: 8158549.8 | C16: 1609965.2 | D16: 110
A17: 2025-04 | B17: 7177984 | C17: 1388411.1 | D17: 100
A18: 2025-05 | B18: 6210795.3 | C18: 1240932.4 | D18: 101
A19: 2025-06 | B19: 7259682.3 | C19: 1486745.5 | D19: 105
A20: 2025-07 | B20: 9432089.3 | C20: 1866301.6 | D20: 120
A21: 2025-08 | B21: 9116986.7 | C21: 1926541.6 | D21: 109
A22: 2025-09 | B22: 7403277.3 | C22: 1424073.2 | D22: 105
A23: 2025-10 | B23: 9315625.2 | C23: 1927927.9 | D23: 112
A24: 2025-11 | B24: 7558035.8 | C24: 1510867.7 | D24: 110
A25: 2025-12 | B25: 7153473.6 | C25: 1433083.9 | D25: 105
A33: Performance by Product Category
A34: Category | B34: Sales (₹) | C34: Profit (₹) | D34: Units Sold
A35: Electronics | B35: 31645209 | C35: 6362324.8 | D35: 1312
A36: Furniture | B36: 31476922 | C36: 6344279.8 | D36: 1319
A37: Clothing | B37: 30181058 | C37: 5953973.5 | D37: 1258
A54: Performance by Region
A55: Region | B55: Sales (₹) | C55: Profit (₹) | D55: Orders
A56: South | B56: 38575509 | C56: 7600223.3 | D56: 522
A57: West | B57: 36402997 | C57: 7368788.2 | D57: 516
A58: North | B58: 18324684 | C58: 3691566.5 | D58: 249
A75: Performance by Sales Representative
A76: Sales Rep | B76: Sales (₹) | C76: Profit (₹) | D76: Orders
A77: Ajay | B77: 25775669 | C77: 5074993.8 | D77: 339
A78: Rahul | B78: 24295450 | C78: 4970469.5 | D78: 326
A79: Sneha | B79: 21670715 | C79: 4307905.6 | D79: 306
A80: Pooja | B80: 21561355 | C80: 4307209.2 | D80: 316
A96: Sales by Payment Method & Top Cities
A97: Payment Method | B97: Sales (₹) | C97: Orders | F97: City | G97: Sales (₹) | H97: Profit (₹)
A98: Cash | B98: 24744884 | C98: 339 | F98: Bangalore | G98: 21409479 | H98: 4302267.1
...

Sheet Dashboard_Data
A1: Order_ID | B1: Order_Date | C1: Month | D1: City | E1: Category | F1: Sales_Rep | G1: Total_Sales | H1: Profit | I1: Match | K1: City | L1: Sales | M1: Profit | N1: Orders | P1: Category | Q1: Sales | R1: Profit | S1: Orders | U1: Sales Rep | V1: Sales | W1: Profit | X1: Orders | Z1: Month | AA1: Sales | AB1: Profit | AC1: Orders
A2: =Sheet1!A2 -> 1001 | B2: =Sheet1!B2 -> 2025-01-01 | C2: =TEXT(Sheet1!B2,"YYYY-MM") -> 2025-01 | D2: =Sheet1!D2 -> Hyderabad | E2: =Sheet1!F2 -> Electronics | F2: =Sheet1!H2 -> Sneha | G2: =Sheet1!K2 -> 73443.6 | H2: =Sheet1!N2 -> 21019.15 | I2: =IF(AND(OR(FilterCity="All",D2=FilterCity),OR(FilterCategory="All",E2=FilterCategory),OR(FilterRep="All",F2=FilterRep),C2>=FilterMonthFrom,C2<=FilterMonthTo),1,0) -> 1 | K2: Bangalore | L2: =SUMPRODUCT(($D$2:$D$1288=K2)*$I$2:$I$1288*$G$2:$G$1288) -> 21409479 | M2: =SUMPRODUCT(($D$2:$D$1288=K2)*$I$2:$I$1288*$H$2:$H$1288) -> 4302267.1 | N2: =SUMPRODUCT(($D$2:$D$1288=K2)*$I$2:$I$1288) -> 276 | P2: Clothing | Q2: =SUMPRODUCT(($E$2:$E$1288=P2)*$I$2:$I$1288*$G$2:$G$1288) -> 30181058 | R2: =SUMPRODUCT(($E$2:$E$1288=P2)*$I$2:$I$1288*$H$2:$H$1288) -> 5953973.5 | S2: =SUMPRODUCT(($E$2:$E$1288=P2)*$I$2:$I$1288) -> 416 | U2: Ajay | V2: =SUMPRODUCT(($F$2:$F$1288=U2)*$I$2:$I$1288*$G$2:$G$1288) -> 25775669 | W2: =SUMPRODUCT(($F$2:$F$1288=U2)*$I$2:$I$1288*$H$2:$H$1288) -> 5074993.8 | X2: =SUMPRODUCT(($F$2:$F$1288=U2)*$I$2:$I$1288) -> 339 | Z2: 2025-01 | AA2: =SUMPRODUCT(($C$2:$C$1288=Z2)*$I$2:$I$1288*$G$2:$G$1288) -> 8230898.9 | AB2: =SUMPRODUCT(($C$2:$C$1288=Z2)*$I$2:$I$1288*$H$2:$H$1288) -> 1554667.9 | AC2: =SUMPRODUCT(($C$2:$C$1288=Z2)*$I$2:$I$1288) -> 108
A3: =Sheet1!A3 -> 1002 | B3: =Sheet1!B3 -> 2025-01-01 | C3: =TEXT(Sheet1!B3,"YYYY-MM") -> 2025-01 | D3: =Sheet1!D3 -> Delhi | E3: =Sheet1!F3 -> Electronics | F3: =Sheet1!H3 -> Ajay | G3: =Sheet1!K3 -> 66424 | H3: =Sheet1!N3 -> 15368.62 | I3: =IF(AND(OR(FilterCity="All",D3=FilterCity),OR(FilterCategory="All",E3=FilterCategory),OR(FilterRep="All",F3=FilterRep),C3>=FilterMonthFrom,C3<=FilterMonthTo),1,0) -> 1 | K3: Delhi | L3: =SUMPRODUCT(($D$2:$D$1288=K3)*$I$2:$I$1288*$G$2:$G$1288) -> 18324684 | M3: =SUMPRODUCT(($D$2:$D$1288=K3)*$I$2:$I$1288*$H$2:$H$1288) -> 3691566.5 | N3: =SUMPRODUCT(($D$2:$D$1288=K3)*$I$2:$I$1288) -> 249 | P3: Electronics | Q3: =SUMPRODUCT(($E$2:$E$1288=P3)*$I$2:$I$1288*$G$2:$G$1288) -> 31645209 | R3: =SUMPRODUCT(($E$2:$E$1288=P3)*$I$2:$I$1288*$H$2:$H$1288) -> 6362324.8 | S3: =SUMPRODUCT(($E$2:$E$1288=P3)*$I$2:$I$1288) -> 428 | U3: Pooja | V3: =SUMPRODUCT(($F$2:$F$1288=U3)*$I$2:$I$1288*$G$2:$G$1288) -> 21561355 | W3: =SUMPRODUCT(($F$2:$F$1288=U3)*$I$2:$I$1288*$H$2:$H$1288) -> 4307209.2 | X3: =SUMPRODUCT(($F$2:$F$1288=U3)*$I$2:$I$1288) -> 316 | Z3: 2025-02 | AA3: =SUMPRODUCT(($C$2:$C$1288=Z3)*$I$2:$I$1288*$G$2:$G$1288) -> 6285791.3 | AB3: =SUMPRODUCT(($C$2:$C$1288=Z3)*$I$2:$I$1288*$H$2:$H$1288) -> 1291060.2 | AC3: =SUMPRODUCT(($C$2:$C$1288=Z3)*$I$2:$I$1288) -> 102
A4: =Sheet1!A4 -> 1003 | B4: =Sheet1!B4 -> 2025-01-01 | C4: =TEXT(Sheet1!B4,"YYYY-MM") -> 2025-01 | D4: =Sheet1!D4 -> Hyderabad | E4: =Sheet1!F4 -> Furniture | F4: =Sheet1!H4 -> Rahul | G4: =Sheet1!K4 -> 18542.7 | H4: =Sheet1!N4 -> 3595.24 | I4: =IF(AND(OR(FilterCity="All",D4=FilterCity),OR(FilterCategory="All",E4=FilterCategory),OR(FilterRep="All",F4=FilterRep),C4>=FilterMonthFrom,C4<=FilterMonthTo),1,0) -> 1 | K4: Hyderabad | L4: =SUMPRODUCT(($D$2:$D$1288=K4)*$I$2:$I$1288*$G$2:$G$1288) -> 17166030 | M4: =SUMPRODUCT(($D$2:$D$1288=K4)*$I$2:$I$1288*$H$2:$H$1288) -> 3297956.2 | N4: =SUMPRODUCT(($D$2:$D$1288=K4)*$I$2:$I$1288) -> 246 | P4: Furniture | Q4: =SUMPRODUCT(($E$2:$E$1288=P4)*$I$2:$I$1288*$G$2:$G$1288) -> 31476922 | R4: =SUMPRODUCT(($E$2:$E$1288=P4)*$I$2:$I$1288*$H$2:$H$1288) -> 6344279.8 | S4: =SUMPRODUCT(($E$2:$E$1288=P4)*$I$2:$I$1288) -> 443 | U4: Rahul | V4: =SUMPRODUCT(($F$2:$F$1288=U4)*$I$2:$I$1288*$G$2:$G$1288) -> 24295450 | W4: =SUMPRODUCT(($F$2:$F$1288=U4)*$I$2:$I$1288*$H$2:$H$1288) -> 4970469.5 | X4: =SUMPRODUCT(($F$2:$F$1288=U4)*$I$2:$I$1288) -> 326 | Z4: 2025-03 | AA4: =SUMPRODUCT(($C$2:$C$1288=Z4)*$I$2:$I$1288*$G$2:$G$1288) -> 8158549.8 | AB4: =SUMPRODUCT(($C$2:$C$1288=Z4)*$I$2:$I$1288*$H$2:$H$1288) -> 1609965.2 | AC4: =SUMPRODUCT(($C$2:$C$1288=Z4)*$I$2:$I$1288) -> 110
A5: =Sheet1!A5 -> 1004 | B5: =Sheet1!B5 -> 2025-01-02 | C5: =TEXT(Sheet1!B5,"YYYY-MM") -> 2025-01 | D5: =Sheet1!D5 -> Hyderabad | E5: =Sheet1!F5 -> Clothing | F5: =Sheet1!H5 -> Rahul | G5: =Sheet1!K5 -> 71574 | H5: =Sheet1!N5 -> 10999.85 | I5: =IF(AND(OR(FilterCity="All",D5=FilterCity),OR(FilterCategory="All",E5=FilterCategory),OR(FilterRep="All",F5=FilterRep),C5>=FilterMonthFrom,C5<=FilterMonthTo),1,0) -> 1 | K5: Mumbai | L5: =SUMPRODUCT(($D$2:$D$1288=K5)*$I$2:$I$1288*$G$2:$G$1288) -> 17674170 | M5: =SUMPRODUCT(($D$2:$D$1288=K5)*$I$2:$I$1288*$H$2:$H$1288) -> 3571213.4 | N5: =SUMPRODUCT(($D$2:$D$1288=K5)*$I$2:$I$1288) -> 253 | U5: Sneha | V5: =SUMPRODUCT(($F$2:$F$1288=U5)*$I$2:$I$1288*$G$2:$G$1288) -> 21670715 | W5: =SUMPRODUCT(($F$2:$F$1288=U5)*$I$2:$I$1288*$H$2:$H$1288) -> 4307905.6 | X5: =SUMPRODUCT(($F$2:$F$1288=U5)*$I$2:$I$1288) -> 306 | Z5: 2025-04 | AA5: =SUMPRODUCT(($C$2:$C$1288=Z5)*$I$2:$I$1288*$G$2:$G$1288) -> 7177984.1 | AB5: =SUMPRODUCT(($C$2:$C$1288=Z5)*$I$2:$I$1288*$H$2:$H$1288) -> 1388411.1 | AC5: =SUMPRODUCT(($C$2:$C$1288=Z5)*$I$2:$I$1288) -> 100
A6: =Sheet1!A6 -> 1005 | B6: =Sheet1!B6 -> 2025-01-02 | C6: =TEXT(Sheet1!B6,"YYYY-MM") -> 2025-01 | D6: =Sheet1!D6 -> Mumbai | E6: =Sheet1!F6 -> Furniture | F6: =Sheet1!H6 -> Pooja | G6: =Sheet1!K6 -> 206980 | H6: =Sheet1!N6 -> 34168.81 | I6: =IF(AND(OR(FilterCity="All",D6=FilterCity),OR(FilterCategory="All",E6=FilterCategory),OR(FilterRep="All",F6=FilterRep),C6>=FilterMonthFrom,C6<=FilterMonthTo),1,0) -> 1 | K6: Pune | L6: =SUMPRODUCT(($D$2:$D$1288=K6)*$I$2:$I$1288*$G$2:$G$1288) -> 18728827 | M6: =SUMPRODUCT(($D$2:$D$1288=K6)*$I$2:$I$1288*$H$2:$H$1288) -> 3797574.8 | N6: =SUMPRODUCT(($D$2:$D$1288=K6)*$I$2:$I$1288) -> 263 | Z6: 2025-05 | AA6: =SUMPRODUCT(($C$2:$C$1288=Z6)*$I$2:$I$1288*$G$2:$G$1288) -> 6210795.3 | AB6: =SUMPRODUCT(($C$2:$C$1288=Z6)*$I$2:$I$1288*$H$2:$H$1288) -> 1240932.4 | AC6: =SUMPRODUCT(($C$2:$C$1288=Z6)*$I$2:$I$1288) -> 101
A7: =Sheet1!A7 -> 1006 | B7: =Sheet1!B7 -> 2025-01-03 | C7: =TEXT(Sheet1!B7,"YYYY-MM") -> 2025-01 | D7: =Sheet1!D7 -> Hyderabad | E7: =Sheet1!F7 -> Furniture | F7: =Sheet1!H7 -> Ajay | G7: =Sheet1!K7 -> 157960 | H7: =Sheet1!N7 -> 21390.53 | I7: =IF(AND(OR(FilterCity="All",D7=FilterCity),OR(FilterCategory="All",E7=FilterCategory),OR(FilterRep="All",F7=FilterRep),C7>=FilterMonthFrom,C7<=FilterMonthTo),1,0) -> 1 | Z7: 2025-06 | AA7: =SUMPRODUCT(($C$2:$C$1288=Z7)*$I$2:$I$1288*$G$2:$G$1288) -> 7259682.3 | AB7: =SUMPRODUCT(($C$2:$C$1288=Z7)*$I$2:$I$1288*$H$2:$H$1288) -> 1486745.5 | AC7: =SUMPRODUCT(($C$2:$C$1288=Z7)*$I$2:$I$1288) -> 105
A8: =Sheet1!A8 -> 1007 | B8: =Sheet1!B8 -> 2025-01-03 | C8: =TEXT(Sheet1!B8,"YYYY-MM") -> 2025-01 | D8: =Sheet1!D8 -> Pune | E8: =Sheet1!F8 -> Electronics | F8: =Sheet1!H8 -> Rahul | G8: =Sheet1!K8 -> 113745 | H8: =Sheet1!N8 -> 30022.96 | I8: =IF(AND(OR(FilterCity="All",D8=FilterCity),OR(FilterCategory="All",E8=FilterCategory),OR(FilterRep="All",F8=FilterRep),C8>=FilterMonthFrom,C8<=FilterMonthTo),1,0) -> 1 | Z8: 2025-07 | AA8: =SUMPRODUCT(($C$2:$C$1288=Z8)*$I$2:$I$1288*$G$2:$G$1288) -> 9432089.3 | AB8: =SUMPRODUCT(($C$2:$C$1288=Z8)*$I$2:$I$1288*$H$2:$H$1288) -> 1866301.6 | AC8: =SUMPRODUCT(($C$2:$C$1288=Z8)*$I$2:$I$1288) -> 120
A9: =Sheet1!A9 -> 1008 | B9: =Sheet1!B9 -> 2025-01-04 | C9: =TEXT(Sheet1!B9,"YYYY-MM") -> 2025-01 | D9: =Sheet1!D9 -> Mumbai | E9: =Sheet1!F9 -> Electronics | F9: =Sheet1!H9 -> Rahul | G9: =Sheet1!K9 -> 36916.05 | H9: =Sheet1!N9 -> 6036.85 | I9: =IF(AND(OR(FilterCity="All",D9=FilterCity),OR(FilterCategory="All",E9=FilterCategory),OR(FilterRep="All",F9=FilterRep),C9>=FilterMonthFrom,C9<=FilterMonthTo),1,0) -> 1 | Z9: 2025-08 | AA9: =SUMPRODUCT(($C$2:$C$1288=Z9)*$I$2:$I$1288*$G$2:$G$1288) -> 9116986.7 | AB9: =SUMPRODUCT(($C$2:$C$1288=Z9)*$I$2:$I$1288*$H$2:$H$1288) -> 1926541.6 | AC9: =SUMPRODUCT(($C$2:$C$1288=Z9)*$I$2:$I$1288) -> 109
A10: =Sheet1!A10 -> 1009 | B10: =Sheet1!B10 -> 2025-01-04 | C10: =TEXT(Sheet1!B10,"YYYY-MM") -> 2025-01 | D10: =Sheet1!D10 -> Mumbai | E10: =Sheet1!F10 -> Clothing | F10: =Sheet1!H10 -> Sneha | G10: =Sheet1!K10 -> 71020.8 | H10: =Sheet1!N10 -> 8473.11 | I10: =IF(AND(OR(FilterCity="All",D10=FilterCity),OR(FilterCategory="All",E10=FilterCategory),OR(FilterRep="All",F10=FilterRep),C10>=FilterMonthFrom,C10<=FilterMonthTo),1,0) -> 1 | Z10: 2025-09 | AA10: =SUMPRODUCT(($C$2:$C$1288=Z10)*$I$2:$I$1288*$G$2:$G$1288) -> 7403277.3 | AB10: =SUMPRODUCT(($C$2:$C$1288=Z10)*$I$2:$I$1288*$H$2:$H$1288) -> 1424073.2 | AC10: =SUMPRODUCT(($C$2:$C$1288=Z10)*$I$2:$I$1288) -> 105
A11: =Sheet1!A11 -> 1010 | B11: =Sheet1!B11 -> 2025-01-04 | C11: =TEXT(Sheet1!B11,"YYYY-MM") -> 2025-01 | D11: =Sheet1!D11 -> Mumbai | E11: =Sheet1!F11 -> Clothing | F11: =Sheet1!H11 -> Rahul | G11: =Sheet1!K11 -> 67974.5 | H11: =Sheet1!N11 -> 12850.43 | I11: =IF(AND(OR(FilterCity="All",D11=FilterCity),OR(FilterCategory="All",E11=FilterCategory),OR(FilterRep="All",F11=FilterRep),C11>=FilterMonthFrom,C11<=FilterMonthTo),1,0) -> 1 | Z11: 2025-10 | AA11: =SUMPRODUCT(($C$2:$C$1288=Z11)*$I$2:$I$1288*$G$2:$G$1288) -> 9315625.1 | AB11: =SUMPRODUCT(($C$2:$C$1288=Z11)*$I$2:$I$1288*$H$2:$H$1288) -> 1927927.9 | AC11: =SUMPRODUCT(($C$2:$C$1288=Z11)*$I$2:$I$1288) -> 112
A12: =Sheet1!A12 -> 1011 | B12: =Sheet1!B12 -> 2025-01-05 | C12: =TEXT(Sheet1!B12,"YYYY-MM") -> 2025-01 | D12: =Sheet1!D12 -> Mumbai | E12: =Sheet1!F12 -> Electronics | F12: =Sheet1!H12 -> Ajay | G12: =Sheet1!K12 -> 58587.45 | H12: =Sheet1!N12 -> 6595.92 | I12: =IF(AND(OR(FilterCity="All",D12=FilterCity),OR(FilterCategory="All",E12=FilterCategory),OR(FilterRep="All",F12=FilterRep),C12>=FilterMonthFrom,C12<=FilterMonthTo),1,0) -> 1 | Z12: 2025-11 | AA12: =SUMPRODUCT(($C$2:$C$1288=Z12)*$I$2:$I$1288*$G$2:$G$1288) -> 7558035.8 | AB12: =SUMPRODUCT(($C$2:$C$1288=Z12)*$I$2:$I$1288*$H$2:$H$1288) -> 1510867.7 | AC12: =SUMPRODUCT(($C$2:$C$1288=Z12)*$I$2:$I$1288) -> 110
A13: =Sheet1!A13 -> 1012 | B13: =Sheet1!B13 -> 2025-01-05 | C13: =TEXT(Sheet1!B13,"YYYY-MM") -> 2025-01 | D13: =Sheet1!D13 -> Hyderabad | E13: =Sheet1!F13 -> Electronics | F13: =Sheet1!H13 -> Ajay | G13: =Sheet1!K13 -> 1829.7 | H13: =Sheet1!N13 -> 199.21 | I13: =IF(AND(OR(FilterCity="All",D13=FilterCity),OR(FilterCategory="All",E13=FilterCategory),OR(FilterRep="All",F13=FilterRep),C13>=FilterMonthFrom,C13<=FilterMonthTo),1,0) -> 1 | Z13: 2025-12 | AA13: =SUMPRODUCT(($C$2:$C$1288=Z13)*$I$2:$I$1288*$G$2:$G$1288) -> 7153473.6 | AB13: =SUMPRODUCT(($C$2:$C$1288=Z13)*$I$2:$I$1288*$H$2:$H$1288) -> 1433083.9 | AC13: =SUMPRODUCT(($C$2:$C$1288=Z13)*$I$2:$I$1288) -> 105
A14: =Sheet1!A14 -> 1013 | B14: =Sheet1!B14 -> 2025-01-05 | C14: =TEXT(Sheet1!B14,"YYYY-MM") -> 2025-01 | D14: =Sheet1!D14 -> Bangalore | E14: =Sheet1!F14 -> Electronics | F14: =Sheet1!H14 -> Pooja | G14: =Sheet1!K14 -> 80271.2 | H14: =Sheet1!N14 -> 15340.73 | I14: =IF(AND(OR(FilterCity="All",D14=FilterCity),OR(FilterCategory="All",E14=FilterCategory),OR(FilterRep="All",F14=FilterRep),C14>=FilterMonthFrom,C14<=FilterMonthTo),1,0) -> 1
A15: =Sheet1!A15 -> 1014 | B15: =Sheet1!B15 -> 2025-01-05 | C15: =TEXT(Sheet1!B15,"YYYY-MM") -> 2025-01 | D15: =Sheet1!D15 -> Mumbai | E15: =Sheet1!F15 -> Furniture | F15: =Sheet1!H15 -> Sneha | G15: =Sheet1!K15 -> 129538.8 | H15: =Sheet1!N15 -> 21019.95 | I15: =IF(AND(OR(FilterCity="All",D15=FilterCity),OR(FilterCategory="All",E15=FilterCategory),OR(FilterRep="All",F15=FilterRep),C15>=FilterMonthFrom,C15<=FilterMonthTo),1,0) -> 1
A16: =Sheet1!A16 -> 1015 | B16: =Sheet1!B16 -> 2025-01-06 | C16: =TEXT(Sheet1!B16,"YYYY-MM") -> 2025-01 | D16: =Sheet1!D16 -> Mumbai | E16: =Sheet1!F16 -> Electronics | F16: =Sheet1!H16 -> Ajay | G16: =Sheet1!K16 -> 82834 | H16: =Sheet1!N16 -> 13758.71 | I16: =IF(AND(OR(FilterCity="All",D16=FilterCity),OR(FilterCategory="All",E16=FilterCategory),OR(FilterRep="All",F16=FilterRep),C16>=FilterMonthFrom,C16<=FilterMonthTo),1,0) -> 1
A17: =Sheet1!A17 -> 1016 | B17: =Sheet1!B17 -> 2025-01-06 | C17: =TEXT(Sheet1!B17,"YYYY-MM") -> 2025-01 | D17: =Sheet1!D17 -> Pune | E17: =Sheet1!F17 -> Furniture | F17: =Sheet1!H17 -> Rahul | G17: =Sheet1!K17 -> 12194 | H17: =Sheet1!N17 -> 2550.47 | I17: =IF(AND(OR(FilterCity="All",D17=FilterCity),OR(FilterCategory="All",E17=FilterCategory),OR(FilterRep="All",F17=FilterRep),C17>=FilterMonthFrom,C17<=FilterMonthTo),1,0) -> 1
A18: =Sheet1!A18 -> 1017 | B18: =Sheet1!B18 -> 2025-01-06 | C18: =TEXT(Sheet1!B18,"YYYY-MM") -> 2025-01 | D18: =Sheet1!D18 -> Delhi | E18: =Sheet1!F18 -> Clothing | F18: =Sheet1!H18 -> Sneha | G18: =Sheet1!K18 -> 141835.5 | H18: =Sheet1!N18 -> 21722.95 | I18: =IF(AND(OR(FilterCity="All",D18=FilterCity),OR(FilterCategory="All",E18=FilterCategory),OR(FilterRep="All",F18=FilterRep),C18>=FilterMonthFrom,C18<=FilterMonthTo),1,0) -> 1
A19: =Sheet1!A19 -> 1018 | B19: =Sheet1!B19 -> 2025-01-06 | C19: =TEXT(Sheet1!B19,"YYYY-MM") -> 2025-01 | D19: =Sheet1!D19 -> Delhi | E19: =Sheet1!F19 -> Furniture | F19: =Sheet1!H19 -> Rahul | G19: =Sheet1!K19 -> 42340 | H19: =Sheet1!N19 -> 5531.83 | I19: =IF(AND(OR(FilterCity="All",D19=FilterCity),OR(FilterCategory="All",E19=FilterCategory),OR(FilterRep="All",F19=FilterRep),C19>=FilterMonthFrom,C19<=FilterMonthTo),1,0) -> 1
A20: =Sheet1!A20 -> 1019 | B20: =Sheet1!B20 -> 2025-01-06 | C20: =TEXT(Sheet1!B20,"YYYY-MM") -> 2025-01 | D20: =Sheet1!D20 -> Hyderabad | E20: =Sheet1!F20 -> Furniture | F20: =Sheet1!H20 -> Rahul | G20: =Sheet1!K20 -> 8504 | H20: =Sheet1!N20 -> 1015.88 | I20: =IF(AND(OR(FilterCity="All",D20=FilterCity),OR(FilterCategory="All",E20=FilterCategory),OR(FilterRep="All",F20=FilterRep),C20>=FilterMonthFrom,C20<=FilterMonthTo),1,0) -> 1
A21: =Sheet1!A21 -> 1020 | B21: =Sheet1!B21 -> 2025-01-07 | C21: =TEXT(Sheet1!B21,"YYYY-MM") -> 2025-01 | D21: =Sheet1!D21 -> Mumbai | E21: =Sheet1!F21 -> Furniture | F21: =Sheet1!H21 -> Pooja | G21: =Sheet1!K21 -> 21092.85 | H21: =Sheet1!N21 -> 3948.81 | I21: =IF(AND(OR(FilterCity="All",D21=FilterCity),OR(FilterCategory="All",E21=FilterCategory),OR(FilterRep="All",F21=FilterRep),C21>=FilterMonthFrom,C21<=FilterMonthTo),1,0) -> 1
A22: =Sheet1!A22 -> 1021 | B22: =Sheet1!B22 -> 2025-01-07 | C22: =TEXT(Sheet1!B22,"YYYY-MM") -> 2025-01 | D22: =Sheet1!D22 -> Mumbai | E22: =Sheet1!F22 -> Furniture | F22: =Sheet1!H22 -> Rahul | G22: =Sheet1!K22 -> 122557.5 | H22: =Sheet1!N22 -> 22166.05 | I22: =IF(AND(OR(FilterCity="All",D22=FilterCity),OR(FilterCategory="All",E22=FilterCategory),OR(FilterRep="All",F22=FilterRep),C22>=FilterMonthFrom,C22<=FilterMonthTo),1,0) -> 1
A23: =Sheet1!A23 -> 1022 | B23: =Sheet1!B23 -> 2025-01-07 | C23: =TEXT(Sheet1!B23,"YYYY-MM") -> 2025-01 | D23: =Sheet1!D23 -> Hyderabad | E23: =Sheet1!F23 -> Clothing | F23: =Sheet1!H23 -> Ajay | G23: =Sheet1!K23 -> 84360 | H23: =Sheet1!N23 -> 18150.33 | I23: =IF(AND(OR(FilterCity="All",D23=FilterCity),OR(FilterCategory="All",E23=FilterCategory),OR(FilterRep="All",F23=FilterRep),C23>=FilterMonthFrom,C23<=FilterMonthTo),1,0) -> 1
A24: =Sheet1!A24 -> 1023 | B24: =Sheet1!B24 -> 2025-01-08 | C24: =TEXT(Sheet1!B24,"YYYY-MM") -> 2025-01 | D24: =Sheet1!D24 -> Pune | E24: =Sheet1!F24 -> Furniture | F24: =Sheet1!H24 -> Sneha | G24: =Sheet1!K24 -> 12491.6 | H24: =Sheet1!N24 -> 2919.66 | I24: =IF(AND(OR(FilterCity="All",D24=FilterCity),OR(FilterCategory="All",E24=FilterCategory),OR(FilterRep="All",F24=FilterRep),C24>=FilterMonthFrom,C24<=FilterMonthTo),1,0) -> 1
A25: =Sheet1!A25 -> 1024 | B25: =Sheet1!B25 -> 2025-01-08 | C25: =TEXT(Sheet1!B25,"YYYY-MM") -> 2025-01 | D25: =Sheet1!D25 -> Hyderabad | E25: =Sheet1!F25 -> Electronics | F25: =Sheet1!H25 -> Ajay | G25: =Sheet1!K25 -> 41440.9 | H25: =Sheet1!N25 -> 4574.51 | I25: =IF(AND(OR(FilterCity="All",D25=FilterCity),OR(FilterCategory="All",E25=FilterCategory),OR(FilterRep="All",F25=FilterRep),C25>=FilterMonthFrom,C25<=FilterMonthTo),1,0) -> 1
... A1288: =Sheet1!A1288 -> 2287 | B1288: =Sheet1!B1288 -> 2025-12-31 | C1288: =TEXT(Sheet1!B1288,"YYYY-MM") -> 2025-12 | D1288: =Sheet1!D1288 -> Bangalore | E1288: =Sheet1!F1288 -> Electronics | F1288: =Sheet1!H1288 -> Pooja | G1288: =Sheet1!K1288 -> 68656.5 | H1288: =Sheet1!N1288 -> 19918.22 | I1288: =IF(AND(OR(FilterCity="All",D1288=FilterCity),OR(FilterCategory="All",E1288=FilterCategory),OR(FilterRep="All",F1288=FilterRep),C1288>=FilterMonthFrom,C1288<=FilterMonthTo),1,0) -> 1
